Workbook

Sheet Objaśnienia
A1: Analiza frekwencji semestralnej — wszystkie klasy, wszystkie lata
A3: Zrodlo danych
A4: Arkusze zrodlowe: dane/frekw2020_2021.xlsx … dane/frekw2025_2026.xlsx (dziennik elektroniczny, wpisy frekwencji per lekcja).
A5: Zgodnie z analiza_v2_DASHBOARD_FINALNY.ipynb (komorka 5): z kazdego roku wykluczony jest sam 1 wrzesnia (filtr 'Data lekcji' > 'RRRR-09-01', 1 wrzesnia wylacznie).
A7: Wzor frekwencji (zgodny z metodologia uzywana w projekcie — analiza_v2_DASHBOARD_FINALNY.ipynb)
A8: Frekwencja % = (Wszystkich wpisow − Nieobecnosci) / Wszystkich wpisow × 100
A9: Nieobecnosci = wpisy: 'nieobecność', 'nieob. uspraw.', 'nieob. uspr. p.s.'
A10: Do 'obecnosci' (nie liczone jako nieobecnosc) zaliczaja sie: 'obecność', 'nauka zdalna', 'spóźnienie', 'spóźn. uspr.', 'zwolniony' — tak jak w dotychczasowych dashboardach.
A12: Podzial na semestry
A13: W danych zrodlowych brak jawnej kolumny z numerem semestru — granice semestrow zostaly wyznaczone na podstawie przerwy w zajeciach (ferie zimowe) widocznej w datach lekcji w kazdym roku szkolnym:
A14: 2020/2021: semestr I do 2020-12-22 (wlacznie) • semestr II od 2021-01-18 (wlacznie)
A15: 2021/2022: semestr I do 2022-01-28 (wlacznie) • semestr II od 2022-02-14 (wlacznie)
... A35: • Odstający — podsumowanie — jeden wiersz = klasa x semestr: liczba uczniow, liczba odstajacych, % odstajacych, frekwencja z/bez odstajacych (wszystko formulami z arkusza 'Uczniowie').

Sheet Dane szczegółowe
A1: Dziennik (klasa) | B1: Rocznik | C1: Kierunek | D1: Rok szkolny | E1: Semestr | F1: Wszystkich wpisów | G1: Nieobecności | H1: Frekwencja %
A2: 4TRM | B2: 2017 | C2: TRM | D2: 2020/2021 | E2: I | F2: 11363 | G2: 3544 | H2: =(F2-G2)/F2 -> 0.68811053
A3: 4TRM | B3: 2017 | C3: TRM | D3: 2020/2021 | E3: II | F3: 11317 | G3: 3130 | H3: =(F3-G3)/F3 -> 0.72342494
A4: 4TŻ | B4: 2017 | C4: TŻ | D4: 2020/2021 | E4: I | F4: 12667 | G4: 3528 | H4: =(F4-G4)/F4 -> 0.72148101
A5: 4TŻ | B5: 2017 | C5: TŻ | D5: 2020/2021 | E5: II | F5: 11763 | G5: 2855 | H5: =(F5-G5)/F5 -> 0.75728981
A6: 3M | B6: 2018 | C6: M | D6: 2020/2021 | E6: I | F6: 6650 | G6: 2877 | H6: =(F6-G6)/F6 -> 0.56736842
A7: 3M | B7: 2018 | C7: M | D7: 2020/2021 | E7: II | F7: 8750 | G7: 4465 | H7: =(F7-G7)/F7 -> 0.48971429
A8: 3TRM | B8: 2018 | C8: TRM | D8: 2020/2021 | E8: I | F8: 13892 | G8: 2510 | H8: =(F8-G8)/F8 -> 0.81932047
A9: 3TRM | B9: 2018 | C9: TRM | D9: 2020/2021 | E9: II | F9: 18113 | G9: 5088 | H9: =(F9-G9)/F9 -> 0.71909678
A10: 4TRM | B10: 2018 | C10: TRM | D10: 2021/2022 | E10: I | F10: 14569 | G10: 4444 | H10: =(F10-G10)/F10 -> 0.69496877
A11: 4TRM | B11: 2018 | C11: TRM | D11: 2021/2022 | E11: II | F11: 8359 | G11: 3516 | H11: =(F11-G11)/F11 -> 0.57937552
A12: 3TŻ | B12: 2018 | C12: TŻ | D12: 2020/2021 | E12: I | F12: 9338 | G12: 1488 | H12: =(F12-G12)/F12 -> 0.8406511
A13: 3TŻ | B13: 2018 | C13: TŻ | D13: 2020/2021 | E13: II | F13: 14358 | G13: 2315 | H13: =(F13-G13)/F13 -> 0.83876584
... A217: 1TŻ | B217: 2025 | C217: TŻ | D217: 2025/2026 | E217: II | F217: 17299 | G217: 5469 | H217: =(F217-G217)/F217 -> 0.68385456

Sheet Pivot – Frekwencja %
A1: Klasa | B1: 2020/2021 sem. I | C1: 2020/2021 sem. II | D1: 2021/2022 sem. I | E1: 2021/2022 sem. II | F1: 2022/2023 sem. I | G1: 2022/2023 sem. II | H1: 2023/2024 sem. I | I1: 2023/2024 sem. II | J1: 2024/2025 sem. I | K1: 2024/2025 sem. II | L1: 2025/2026 sem. I | M1: 2025/2026 sem. II
A2: 4TRM | B2: ='Dane szczegółowe'!H2 -> 0.68811053 | C2: ='Dane szczegółowe'!H3 -> 0.72342494 | D2: ='Dane szczegółowe'!H10 -> 0.69496877 | E2: ='Dane szczegółowe'!H11 -> 0.57937552
A3: 4TŻ | B3: ='Dane szczegółowe'!H4 -> 0.72148101 | C3: ='Dane szczegółowe'!H5 -> 0.75728981 | D3: ='Dane szczegółowe'!H14 -> 0.77422366 | E3: ='Dane szczegółowe'!H15 -> 0.68766253 | F3: ='Dane szczegółowe'!H52 -> 0.73735714 | G3: ='Dane szczegółowe'!H53 -> 0.58251748
A4: 3M | B4: ='Dane szczegółowe'!H6 -> 0.56736842 | C4: ='Dane szczegółowe'!H7 -> 0.48971429 | F4: ='Dane szczegółowe'!H58 -> 0.62848389 | G4: ='Dane szczegółowe'!H59 -> 0.63240726 | H4: ='Dane szczegółowe'!H94 -> 0.6181794 | I4: ='Dane szczegółowe'!H95 -> 0.58744615 | L4: ='Dane szczegółowe'!H168 -> 0.64995711 | M4: ='Dane szczegółowe'!H169 -> 0.54691708
A5: 3TRM | B5: ='Dane szczegółowe'!H8 -> 0.81932047 | C5: ='Dane szczegółowe'!H9 -> 0.71909678
A6: 4TRM | B6: ='Dane szczegółowe'!H2 -> 0.68811053 | C6: ='Dane szczegółowe'!H3 -> 0.72342494 | D6: ='Dane szczegółowe'!H10 -> 0.69496877 | E6: ='Dane szczegółowe'!H11 -> 0.57937552
A7: 3TŻ | B7: ='Dane szczegółowe'!H12 -> 0.8406511 | C7: ='Dane szczegółowe'!H13 -> 0.83876584 | D7: ='Dane szczegółowe'!H50 -> 0.73281274 | E7: ='Dane szczegółowe'!H51 -> 0.66075146 | L7: ='Dane szczegółowe'!H192 -> 0.7849675 | M7: ='Dane szczegółowe'!H193 -> 0.64693853
A8: 4TŻ | B8: ='Dane szczegółowe'!H4 -> 0.72148101 | C8: ='Dane szczegółowe'!H5 -> 0.75728981 | D8: ='Dane szczegółowe'!H14 -> 0.77422366 | E8: ='Dane szczegółowe'!H15 -> 0.68766253 | F8: ='Dane szczegółowe'!H52 -> 0.73735714 | G8: ='Dane szczegółowe'!H53 -> 0.58251748
A9: 2MK | B9: ='Dane szczegółowe'!H16 -> 0.70404624 | C9: ='Dane szczegółowe'!H17 -> 0.65908738 | H9: ='Dane szczegółowe'!H128 -> 0.72501162 | I9: ='Dane szczegółowe'!H129 -> 0.60932898
A10: 3MK | D10: ='Dane szczegółowe'!H18 -> 0.67377236 | E10: ='Dane szczegółowe'!H19 -> 0.56672175 | J10: ='Dane szczegółowe'!H130 -> 0.69512758 | K10: ='Dane szczegółowe'!H131 -> 0.56838315
A11: 2RŻ5 | B11: ='Dane szczegółowe'!H20 -> 0.81854043 | C11: ='Dane szczegółowe'!H21 -> 0.72874016 | F11: ='Dane szczegółowe'!H98 -> 0.85338902 | G11: ='Dane szczegółowe'!H99 -> 0.69342141
A12: 3RŻ5 | D12: ='Dane szczegółowe'!H22 -> 0.73171727 | E12: ='Dane szczegółowe'!H23 -> 0.65607886 | H12: ='Dane szczegółowe'!H100 -> 0.78102737 | I12: ='Dane szczegółowe'!H101 -> 0.66055406
A13: 4RŻ5 | F13: ='Dane szczegółowe'!H24 -> 0.72435739 | G13: ='Dane szczegółowe'!H25 -> 0.56892876 | J13: ='Dane szczegółowe'!H102 -> 0.74871637 | K13: ='Dane szczegółowe'!H103 -> 0.63977443
A14: 5RŻ5 | H14: ='Dane szczegółowe'!H26 -> 0.67226891 | I14: ='Dane szczegółowe'!H27 -> 0.549219 | L14: ='Dane szczegółowe'!H104 -> 0.74084948 | M14: ='Dane szczegółowe'!H105 -> 0.59082126
A15: 2TM5 | B15: ='Dane szczegółowe'!H28 -> 0.88898418 | C15: ='Dane szczegółowe'!H29 -> 0.8150745 | D15: ='Dane szczegółowe'!H62 -> 0.77905786 | E15: ='Dane szczegółowe'!H63 -> 0.80206779 | F15: ='Dane szczegółowe'!H108 -> 0.80193095 | G15: ='Dane szczegółowe'!H109 -> 0.68245839 | H15: ='Dane szczegółowe'!H134 -> 0.77530125 | I15: ='Dane szczegółowe'!H135 -> 0.68324111
A16: 3TM5 | D16: ='Dane szczegółowe'!H30 -> 0.8077667 | E16: ='Dane szczegółowe'!H31 -> 0.71285815 | F16: ='Dane szczegółowe'!H64 -> 0.77815673 | G16: ='Dane szczegółowe'!H65 -> 0.60498221 | H16: ='Dane szczegółowe'!H110 -> 0.77427732 | I16: ='Dane szczegółowe'!H111 -> 0.58976792 | J16: ='Dane szczegółowe'!H136 -> 0.73987676 | K16: ='Dane szczegółowe'!H137 -> 0.57008368
A17: 4TM5 | F17: ='Dane szczegółowe'!H32 -> 0.82958899 | G17: ='Dane szczegółowe'!H33 -> 0.67578736 | H17: ='Dane szczegółowe'!H66 -> 0.7498564 | I17: ='Dane szczegółowe'!H67 -> 0.53674089 | J17: ='Dane szczegółowe'!H112 -> 0.78906891 | K17: ='Dane szczegółowe'!H113 -> 0.64317389 | L17: ='Dane szczegółowe'!H138 -> 0.74758364 | M17: ='Dane szczegółowe'!H139 -> 0.62989246
A18: 5TM5 | H18: ='Dane szczegółowe'!H34 -> 0.82221815 | I18: ='Dane szczegółowe'!H35 -> 0.61373798 | J18: ='Dane szczegółowe'!H68 -> 0.67887668 | K18: ='Dane szczegółowe'!H69 -> 0.45072115 | L18: ='Dane szczegółowe'!H114 -> 0.67407407 | M18: ='Dane szczegółowe'!H115 -> 0.48324693
A19: 2TMR | B19: ='Dane szczegółowe'!H36 -> 0.79229733 | C19: ='Dane szczegółowe'!H37 -> 0.77964526 | J19: ='Dane szczegółowe'!H172 -> 0.79974908 | K19: ='Dane szczegółowe'!H173 -> 0.66939714
A20: 3TMR | D20: ='Dane szczegółowe'!H38 -> 0.67301179 | E20: ='Dane szczegółowe'!H39 -> 0.64483581 | L20: ='Dane szczegółowe'!H174 -> 0.69065606 | M20: ='Dane szczegółowe'!H175 -> 0.56344524
A21: 4TMR | F21: ='Dane szczegółowe'!H40 -> 0.63401051 | G21: ='Dane szczegółowe'!H41 -> 0.43986874
A22: 2TR | B22: ='Dane szczegółowe'!H42 -> 0.77278494 | C22: ='Dane szczegółowe'!H43 -> 0.73772831 | J22: ='Dane szczegółowe'!H178 -> 0.80175948 | K22: ='Dane szczegółowe'!H179 -> 0.65352002
A23: 3TR | D23: ='Dane szczegółowe'!H44 -> 0.74440486 | E23: ='Dane szczegółowe'!H45 -> 0.67895694 | L23: ='Dane szczegółowe'!H180 -> 0.76430797 | M23: ='Dane szczegółowe'!H181 -> 0.57734375
A24: 4TR | F24: ='Dane szczegółowe'!H46 -> 0.74662709 | G24: ='Dane szczegółowe'!H47 -> 0.57251908
A25: 2TŻ | B25: ='Dane szczegółowe'!H48 -> 0.84415886 | C25: ='Dane szczegółowe'!H49 -> 0.81565566 | J25: ='Dane szczegółowe'!H190 -> 0.8145203 | K25: ='Dane szczegółowe'!H191 -> 0.73380442
A26: 3TŻ | B26: ='Dane szczegółowe'!H12 -> 0.8406511 | C26: ='Dane szczegółowe'!H13 -> 0.83876584 | D26: ='Dane szczegółowe'!H50 -> 0.73281274 | E26: ='Dane szczegółowe'!H51 -> 0.66075146 | L26: ='Dane szczegółowe'!H192 -> 0.7849675 | M26: ='Dane szczegółowe'!H193 -> 0.64693853
A27: 4TŻ | B27: ='Dane szczegółowe'!H4 -> 0.72148101 | C27: ='Dane szczegółowe'!H5 -> 0.75728981 | D27: ='Dane szczegółowe'!H14 -> 0.77422366 | E27: ='Dane szczegółowe'!H15 -> 0.68766253 | F27: ='Dane szczegółowe'!H52 -> 0.73735714 | G27: ='Dane szczegółowe'!H53 -> 0.58251748
A28: 1M | B28: ='Dane szczegółowe'!H54 -> 0.76382838 | C28: ='Dane szczegółowe'!H55 -> 0.72107161 | D28: ='Dane szczegółowe'!H90 -> 0.80452745 | E28: ='Dane szczegółowe'!H91 -> 0.76480206 | H28: ='Dane szczegółowe'!H164 -> 0.76100738 | I28: ='Dane szczegółowe'!H165 -> 0.63258335 | J28: ='Dane szczegółowe'!H194 -> 0.74861045 | K28: ='Dane szczegółowe'!H195 -> 0.66713287 | L28: ='Dane szczegółowe'!H208 -> 0.71615721 | M28: ='Dane szczegółowe'!H209 -> 0.53164673
A29: 2M | D29: ='Dane szczegółowe'!H56 -> 0.69681853 | E29: ='Dane szczegółowe'!H57 -> 0.5533023 | F29: ='Dane szczegółowe'!H92 -> 0.75854568 | G29: ='Dane szczegółowe'!H93 -> 0.58658346 | J29: ='Dane szczegółowe'!H166 -> 0.72103436 | K29: ='Dane szczegółowe'!H167 -> 0.62315416 | L29: ='Dane szczegółowe'!H196 -> 0.7749192 | M29: ='Dane szczegółowe'!H197 -> 0.65756071
A30: 3M | B30: ='Dane szczegółowe'!H6 -> 0.56736842 | C30: ='Dane szczegółowe'!H7 -> 0.48971429 | F30: ='Dane szczegółowe'!H58 -> 0.62848389 | G30: ='Dane szczegółowe'!H59 -> 0.63240726 | H30: ='Dane szczegółowe'!H94 -> 0.6181794 | I30: ='Dane szczegółowe'!H95 -> 0.58744615 | L30: ='Dane szczegółowe'!H168 -> 0.64995711 | M30: ='Dane szczegółowe'!H169 -> 0.54691708
A31: 1TM5 | B31: ='Dane szczegółowe'!H60 -> 0.86086862 | C31: ='Dane szczegółowe'!H61 -> 0.84107128 | D31: ='Dane szczegółowe'!H106 -> 0.84044357 | E31: ='Dane szczegółowe'!H107 -> 0.82003988 | F31: ='Dane szczegółowe'!H132 -> 0.87032391 | G31: ='Dane szczegółowe'!H133 -> 0.75471387
A32: 2TM5 | B32: ='Dane szczegółowe'!H28 -> 0.88898418 | C32: ='Dane szczegółowe'!H29 -> 0.8150745 | D32: ='Dane szczegółowe'!H62 -> 0.77905786 | E32: ='Dane szczegółowe'!H63 -> 0.80206779 | F32: ='Dane szczegółowe'!H108 -> 0.80193095 | G32: ='Dane szczegółowe'!H109 -> 0.68245839 | H32: ='Dane szczegółowe'!H134 -> 0.77530125 | I32: ='Dane szczegółowe'!H135 -> 0.68324111
A33: 3TM5 | D33: ='Dane szczegółowe'!H30 -> 0.8077667 | E33: ='Dane szczegółowe'!H31 -> 0.71285815 | F33: ='Dane szczegółowe'!H64 -> 0.77815673 | G33: ='Dane szczegółowe'!H65 -> 0.60498221 | H33: ='Dane szczegółowe'!H110 -> 0.77427732 | I33: ='Dane szczegółowe'!H111 -> 0.58976792 | J33: ='Dane szczegółowe'!H136 -> 0.73987676 | K33: ='Dane szczegółowe'!H137 -> 0.57008368
A34: 4TM5 | F34: ='Dane szczegółowe'!H32 -> 0.82958899 | G34: ='Dane szczegółowe'!H33 -> 0.67578736 | H34: ='Dane szczegółowe'!H66 -> 0.7498564 | I34: ='Dane szczegółowe'!H67 -> 0.53674089 | J34: ='Dane szczegółowe'!H112 -> 0.78906891 | K34: ='Dane szczegółowe'!H113 -> 0.64317389 | L34: ='Dane szczegółowe'!H138 -> 0.74758364 | M34: ='Dane szczegółowe'!H139 -> 0.62989246
A35: 5TM5 | H35: ='Dane szczegółowe'!H34 -> 0.82221815 | I35: ='Dane szczegółowe'!H35 -> 0.61373798 | J35: ='Dane szczegółowe'!H68 -> 0.67887668 | K35: ='Dane szczegółowe'!H69 -> 0.45072115 | L35: ='Dane szczegółowe'!H114 -> 0.67407407 | M35: ='Dane szczegółowe'!H115 -> 0.48324693
A36: 1TW5 | B36: ='Dane szczegółowe'!H70 -> 0.92805383 | C36: ='Dane szczegółowe'!H71 -> 0.89420601 | D36: ='Dane szczegółowe'!H116 -> 0.84972695 | E36: ='Dane szczegółowe'!H117 -> 0.76647218 | F36: ='Dane szczegółowe'!H148 -> 0.86696521 | G36: ='Dane szczegółowe'!H149 -> 0.725165
A37: 2TW5 | D37: ='Dane szczegółowe'!H72 -> 0.79621494 | E37: ='Dane szczegółowe'!H73 -> 0.7711039 | F37: ='Dane szczegółowe'!H118 -> 0.85681545 | G37: ='Dane szczegółowe'!H119 -> 0.73026896 | H37: ='Dane szczegółowe'!H150 -> 0.83062094 | I37: ='Dane szczegółowe'!H151 -> 0.68043904
A38: 3TW5 | F38: ='Dane szczegółowe'!H74 -> 0.84270094 | G38: ='Dane szczegółowe'!H75 -> 0.66562009 | H38: ='Dane szczegółowe'!H120 -> 0.80130293 | I38: ='Dane szczegółowe'!H121 -> 0.70339992 | J38: ='Dane szczegółowe'!H152 -> 0.76341917 | K38: ='Dane szczegółowe'!H153 -> 0.6180884
A39: 4TW5 | H39: ='Dane szczegółowe'!H76 -> 0.81230769 | I39: ='Dane szczegółowe'!H77 -> 0.74867444 | J39: ='Dane szczegółowe'!H122 -> 0.82014308 | K39: ='Dane szczegółowe'!H123 -> 0.72715957 | L39: ='Dane szczegółowe'!H154 -> 0.77638763 | M39: ='Dane szczegółowe'!H155 -> 0.61047731
A40: 5TW5 | J40: ='Dane szczegółowe'!H78 -> 0.71783574 | K40: ='Dane szczegółowe'!H79 -> 0.63114388 | L40: ='Dane szczegółowe'!H124 -> 0.73943237 | M40: ='Dane szczegółowe'!H125 -> 0.60387586
...

Sheet Podsumowanie roczne
A1: Rok szkolny | B1: Semestr | C1: Średnia frekwencja szkoły % | D1: Liczba klas | E1: Najniższa frekwencja klasy % | F1: Najwyższa frekwencja klasy %
A2: 2020/2021 | B2: I | C2: =IFERROR(AVERAGEIFS('Dane szczegółowe'!$H$2:$H$217,'Dane szczegółowe'!$D$2:$D$217,A2,'Dane szczegółowe'!$E$2:$E$217,B2),"") -> 0.7909633 | D2: =COUNTIFS('Dane szczegółowe'!$D$2:$D$217,A2,'Dane szczegółowe'!$E$2:$E$217,B2) -> 15 | E2: =IFERROR(_xlfn.MINIFS('Dane szczegółowe'!$H$2:$H$217,'Dane szczegółowe'!$D$2:$D$217,A2,'Dane szczegółowe'!$E$2:$E$217,B2),"") -> 0.56736842 | F2: =IFERROR(_xlfn.MAXIFS('Dane szczegółowe'!$H$2:$H$217,'Dane szczegółowe'!$D$2:$D$217,A2,'Dane szczegółowe'!$E$2:$E$217,B2),"") -> 0.92805383
A3: 2020/2021 | B3: II | C3: =IFERROR(AVERAGEIFS('Dane szczegółowe'!$H$2:$H$217,'Dane szczegółowe'!$D$2:$D$217,A3,'Dane szczegółowe'!$E$2:$E$217,B3),"") -> 0.75644555 | D3: =COUNTIFS('Dane szczegółowe'!$D$2:$D$217,A3,'Dane szczegółowe'!$E$2:$E$217,B3) -> 15 | E3: =IFERROR(_xlfn.MINIFS('Dane szczegółowe'!$H$2:$H$217,'Dane szczegółowe'!$D$2:$D$217,A3,'Dane szczegółowe'!$E$2:$E$217,B3),"") -> 0.48971429 | F3: =IFERROR(_xlfn.MAXIFS('Dane szczegółowe'!$H$2:$H$217,'Dane szczegółowe'!$D$2:$D$217,A3,'Dane szczegółowe'!$E$2:$E$217,B3),"") -> 0.89420601
A4: 2021/2022 | B4: I | C4: =IFERROR(AVERAGEIFS('Dane szczegółowe'!$H$2:$H$217,'Dane szczegółowe'!$D$2:$D$217,A4,'Dane szczegółowe'!$E$2:$E$217,B4),"") -> 0.76588367 | D4: =COUNTIFS('Dane szczegółowe'!$D$2:$D$217,A4,'Dane szczegółowe'!$E$2:$E$217,B4) -> 16 | E4: =IFERROR(_xlfn.MINIFS('Dane szczegółowe'!$H$2:$H$217,'Dane szczegółowe'!$D$2:$D$217,A4,'Dane szczegółowe'!$E$2:$E$217,B4),"") -> 0.67301179 | F4: =IFERROR(_xlfn.MAXIFS('Dane szczegółowe'!$H$2:$H$217,'Dane szczegółowe'!$D$2:$D$217,A4,'Dane szczegółowe'!$E$2:$E$217,B4),"") -> 0.85841111
A5: 2021/2022 | B5: II | C5: =IFERROR(AVERAGEIFS('Dane szczegółowe'!$H$2:$H$217,'Dane szczegółowe'!$D$2:$D$217,A5,'Dane szczegółowe'!$E$2:$E$217,B5),"") -> 0.69624024 | D5: =COUNTIFS('Dane szczegółowe'!$D$2:$D$217,A5,'Dane szczegółowe'!$E$2:$E$217,B5) -> 16 | E5: =IFERROR(_xlfn.MINIFS('Dane szczegółowe'!$H$2:$H$217,'Dane szczegółowe'!$D$2:$D$217,A5,'Dane szczegółowe'!$E$2:$E$217,B5),"") -> 0.5533023 | F5: =IFERROR(_xlfn.MAXIFS('Dane szczegółowe'!$H$2:$H$217,'Dane szczegółowe'!$D$2:$D$217,A5,'Dane szczegółowe'!$E$2:$E$217,B5),"") -> 0.82003988
A6: 2022/2023 | B6: I | C6: =IFERROR(AVERAGEIFS('Dane szczegółowe'!$H$2:$H$217,'Dane szczegółowe'!$D$2:$D$217,A6,'Dane szczegółowe'!$E$2:$E$217,B6),"") -> 0.78986509 | D6: =COUNTIFS('Dane szczegółowe'!$D$2:$D$217,A6,'Dane szczegółowe'!$E$2:$E$217,B6) -> 18 | E6: =IFERROR(_xlfn.MINIFS('Dane szczegółowe'!$H$2:$H$217,'Dane szczegółowe'!$D$2:$D$217,A6,'Dane szczegółowe'!$E$2:$E$217,B6),"") -> 0.62848389 | F6: =IFERROR(_xlfn.MAXIFS('Dane szczegółowe'!$H$2:$H$217,'Dane szczegółowe'!$D$2:$D$217,A6,'Dane szczegółowe'!$E$2:$E$217,B6),"") -> 0.89271466
A7: 2022/2023 | B7: II | C7: =IFERROR(AVERAGEIFS('Dane szczegółowe'!$H$2:$H$217,'Dane szczegółowe'!$D$2:$D$217,A7,'Dane szczegółowe'!$E$2:$E$217,B7),"") -> 0.65358772 | D7: =COUNTIFS('Dane szczegółowe'!$D$2:$D$217,A7,'Dane szczegółowe'!$E$2:$E$217,B7) -> 18 | E7: =IFERROR(_xlfn.MINIFS('Dane szczegółowe'!$H$2:$H$217,'Dane szczegółowe'!$D$2:$D$217,A7,'Dane szczegółowe'!$E$2:$E$217,B7),"") -> 0.43986874 | F7: =IFERROR(_xlfn.MAXIFS('Dane szczegółowe'!$H$2:$H$217,'Dane szczegółowe'!$D$2:$D$217,A7,'Dane szczegółowe'!$E$2:$E$217,B7),"") -> 0.75471387
A8: 2023/2024 | B8: I | C8: =IFERROR(AVERAGEIFS('Dane szczegółowe'!$H$2:$H$217,'Dane szczegółowe'!$D$2:$D$217,A8,'Dane szczegółowe'!$E$2:$E$217,B8),"") -> 0.77892908 | D8: =COUNTIFS('Dane szczegółowe'!$D$2:$D$217,A8,'Dane szczegółowe'!$E$2:$E$217,B8) -> 19 | E8: =IFERROR(_xlfn.MINIFS('Dane szczegółowe'!$H$2:$H$217,'Dane szczegółowe'!$D$2:$D$217,A8,'Dane szczegółowe'!$E$2:$E$217,B8),"") -> 0.6181794 | F8: =IFERROR(_xlfn.MAXIFS('Dane szczegółowe'!$H$2:$H$217,'Dane szczegółowe'!$D$2:$D$217,A8,'Dane szczegółowe'!$E$2:$E$217,B8),"") -> 0.85619946
A9: 2023/2024 | B9: II | C9: =IFERROR(AVERAGEIFS('Dane szczegółowe'!$H$2:$H$217,'Dane szczegółowe'!$D$2:$D$217,A9,'Dane szczegółowe'!$E$2:$E$217,B9),"") -> 0.65876676 | D9: =COUNTIFS('Dane szczegółowe'!$D$2:$D$217,A9,'Dane szczegółowe'!$E$2:$E$217,B9) -> 19 | E9: =IFERROR(_xlfn.MINIFS('Dane szczegółowe'!$H$2:$H$217,'Dane szczegółowe'!$D$2:$D$217,A9,'Dane szczegółowe'!$E$2:$E$217,B9),"") -> 0.53674089 | F9: =IFERROR(_xlfn.MAXIFS('Dane szczegółowe'!$H$2:$H$217,'Dane szczegółowe'!$D$2:$D$217,A9,'Dane szczegółowe'!$E$2:$E$217,B9),"") -> 0.76703378
A10: 2024/2025 | B10: I | C10: =IFERROR(AVERAGEIFS('Dane szczegółowe'!$H$2:$H$217,'Dane szczegółowe'!$D$2:$D$217,A10,'Dane szczegółowe'!$E$2:$E$217,B10),"") -> 0.77082371 | D10: =COUNTIFS('Dane szczegółowe'!$D$2:$D$217,A10,'Dane szczegółowe'!$E$2:$E$217,B10) -> 20 | E10: =IFERROR(_xlfn.MINIFS('Dane szczegółowe'!$H$2:$H$217,'Dane szczegółowe'!$D$2:$D$217,A10,'Dane szczegółowe'!$E$2:$E$217,B10),"") -> 0.67887668 | F10: =IFERROR(_xlfn.MAXIFS('Dane szczegółowe'!$H$2:$H$217,'Dane szczegółowe'!$D$2:$D$217,A10,'Dane szczegółowe'!$E$2:$E$217,B10),"") -> 0.85492118
A11: 2024/2025 | B11: II | C11: =IFERROR(AVERAGEIFS('Dane szczegółowe'!$H$2:$H$217,'Dane szczegółowe'!$D$2:$D$217,A11,'Dane szczegółowe'!$E$2:$E$217,B11),"") -> 0.64879443 | D11: =COUNTIFS('Dane szczegółowe'!$D$2:$D$217,A11,'Dane szczegółowe'!$E$2:$E$217,B11) -> 20 | E11: =IFERROR(_xlfn.MINIFS('Dane szczegółowe'!$H$2:$H$217,'Dane szczegółowe'!$D$2:$D$217,A11,'Dane szczegółowe'!$E$2:$E$217,B11),"") -> 0.45072115 | F11: =IFERROR(_xlfn.MAXIFS('Dane szczegółowe'!$H$2:$H$217,'Dane szczegółowe'!$D$2:$D$217,A11,'Dane szczegółowe'!$E$2:$E$217,B11),"") -> 0.73380442
A12: 2025/2026 | B12: I | C12: =IFERROR(AVERAGEIFS('Dane szczegółowe'!$H$2:$H$217,'Dane szczegółowe'!$D$2:$D$217,A12,'Dane szczegółowe'!$E$2:$E$217,B12),"") -> 0.76857621 | D12: =COUNTIFS('Dane szczegółowe'!$D$2:$D$217,A12,'Dane szczegółowe'!$E$2:$E$217,B12) -> 20 | E12: =IFERROR(_xlfn.MINIFS('Dane szczegółowe'!$H$2:$H$217,'Dane szczegółowe'!$D$2:$D$217,A12,'Dane szczegółowe'!$E$2:$E$217,B12),"") -> 0.64995711 | F12: =IFERROR(_xlfn.MAXIFS('Dane szczegółowe'!$H$2:$H$217,'Dane szczegółowe'!$D$2:$D$217,A12,'Dane szczegółowe'!$E$2:$E$217,B12),"") -> 0.90180823
A13: 2025/2026 | B13: II | C13: =IFERROR(AVERAGEIFS('Dane szczegółowe'!$H$2:$H$217,'Dane szczegółowe'!$D$2:$D$217,A13,'Dane szczegółowe'!$E$2:$E$217,B13),"") -> 0.62166696 | D13: =COUNTIFS('Dane szczegółowe'!$D$2:$D$217,A13,'Dane szczegółowe'!$E$2:$E$217,B13) -> 20 | E13: =IFERROR(_xlfn.MINIFS('Dane szczegółowe'!$H$2:$H$217,'Dane szczegółowe'!$D$2:$D$217,A13,'Dane szczegółowe'!$E$2:$E$217,B13),"") -> 0.48324693 | F13: =IFERROR(_xlfn.MAXIFS('Dane szczegółowe'!$H$2:$H$217,'Dane szczegółowe'!$D$2:$D$217,A13,'Dane szczegółowe'!$E$2:$E$217,B13),"") -> 0.76565361

Sheet Uczniowie (zanonimizowani)
A1: ID ucznia | B1: Dziennik | C1: Rocznik | D1: Kierunek | E1: Rok szkolny | F1: Semestr | G1: Wszystkich wpisów | H1: Nieobecności | I1: Frekwencja % | J1: Dolna granica IQR (grupy) | K1: Odstający | M1: Nota: kolumna J ("Dolna granica IQR") to Q1 - 1,5*(Q3-Q1) frekwencji w danej grupie klasa x rok x semestr,
A2: 02459A03BA | B2: 4TRM | C2: 2017 | D2: TRM | E2: 2020/2021 | F2: I | G2: 451 | H2: 182 | I2: =(G2-H2)/G2 -> 0.59645233 | J2: 0.432 | K2: =IF(I2<J2,"TAK","NIE") -> NIE | M2: wyliczona raz skryptem (jak w analiza_v2_DASHBOARD_FINALNY.ipynb) i wpisana jako wartosc - kolumna K jest juz formula porownujaca.
A3: 0357F27F80 | B3: 4TRM | C3: 2017 | D3: TRM | E3: 2020/2021 | F3: I | G3: 451 | H3: 320 | I3: =(G3-H3)/G3 -> 0.29046563 | J3: 0.432 | K3: =IF(I3<J3,"TAK","NIE") -> TAK
A4: 0767EE8E89 | B4: 4TRM | C4: 2017 | D4: TRM | E4: 2020/2021 | F4: I | G4: 509 | H4: 127 | I4: =(G4-H4)/G4 -> 0.75049116 | J4: 0.432 | K4: =IF(I4<J4,"TAK","NIE") -> NIE
A5: 1D9E98524E | B5: 4TRM | C5: 2017 | D5: TRM | E5: 2020/2021 | F5: I | G5: 437 | H5: 186 | I5: =(G5-H5)/G5 -> 0.57437071 | J5: 0.432 | K5: =IF(I5<J5,"TAK","NIE") -> NIE
A6: 232AD4E8C9 | B6: 4TRM | C6: 2017 | D6: TRM | E6: 2020/2021 | F6: I | G6: 949 | H6: 251 | I6: =(G6-H6)/G6 -> 0.73551106 | J6: 0.432 | K6: =IF(I6<J6,"TAK","NIE") -> NIE
A7: 286673718A | B7: 4TRM | C7: 2017 | D7: TRM | E7: 2020/2021 | F7: I | G7: 437 | H7: 104 | I7: =(G7-H7)/G7 -> 0.76201373 | J7: 0.432 | K7: =IF(I7<J7,"TAK","NIE") -> NIE
A8: 2C93123F98 | B8: 4TRM | C8: 2017 | D8: TRM | E8: 2020/2021 | F8: I | G8: 437 | H8: 108 | I8: =(G8-H8)/G8 -> 0.75286041 | J8: 0.432 | K8: =IF(I8<J8,"TAK","NIE") -> NIE
A9: 3ADFC77172 | B9: 4TRM | C9: 2017 | D9: TRM | E9: 2020/2021 | F9: I | G9: 509 | H9: 191 | I9: =(G9-H9)/G9 -> 0.62475442 | J9: 0.432 | K9: =IF(I9<J9,"TAK","NIE") -> NIE
A10: 624B4E765C | B10: 4TRM | C10: 2017 | D10: TRM | E10: 2020/2021 | F10: I | G10: 451 | H10: 101 | I10: =(G10-H10)/G10 -> 0.77605322 | J10: 0.432 | K10: =IF(I10<J10,"TAK","NIE") -> NIE
A11: 8E42C053AF | B11: 4TRM | C11: 2017 | D11: TRM | E11: 2020/2021 | F11: I | G11: 437 | H11: 156 | I11: =(G11-H11)/G11 -> 0.64302059 | J11: 0.432 | K11: =IF(I11<J11,"TAK","NIE") -> NIE
A12: 94A48F07F3 | B12: 4TRM | C12: 2017 | D12: TRM | E12: 2020/2021 | F12: I | G12: 509 | H12: 92 | I12: =(G12-H12)/G12 -> 0.81925344 | J12: 0.432 | K12: =IF(I12<J12,"TAK","NIE") -> NIE
A13: 9FC8DBDC1F | B13: 4TRM | C13: 2017 | D13: TRM | E13: 2020/2021 | F13: I | G13: 509 | H13: 77 | I13: =(G13-H13)/G13 -> 0.84872299 | J13: 0.432 | K13: =IF(I13<J13,"TAK","NIE") -> NIE
A14: A5C7DFE9C7 | B14: 4TRM | C14: 2017 | D14: TRM | E14: 2020/2021 | F14: I | G14: 488 | H14: 138 | I14: =(G14-H14)/G14 -> 0.71721311 | J14: 0.432 | K14: =IF(I14<J14,"TAK","NIE") -> NIE
... A4580: E8CAE060C5 | B4580: 1TŻ | C4580: 2025 | D4580: TŻ | E4580: 2025/2026 | F4580: II | G4580: 696 | H4580: 154 | I4580: =(G4580-H4580)/G4580 -> 0.77873563 | J4580: 0.405 | K4580: =IF(I4580<J4580,"TAK","NIE") -> NIE

Sheet Odstający – podsumowanie
A1: Rok szkolny | B1: Semestr | C1: Dziennik | D1: Liczba uczniów | E1: Liczba odstających | F1: % odstających | G1: Śr. frekwencja z odstającymi | H1: Śr. frekwencja bez odstających | I1: Różnica
A2: 2020/2021 | B2: I | C2: 1M | D2: =COUNTIFS('Uczniowie (zanonimizowani)'!$B$2:$B$4580,C2,'Uczniowie (zanonimizowani)'!$E$2:$E$4580,A2,'Uczniowie (zanonimizowani)'!$F$2:$F$4580,B2) -> 15 | E2: =COUNTIFS('Uczniowie (zanonimizowani)'!$B$2:$B$4580,C2,'Uczniowie (zanonimizowani)'!$E$2:$E$4580,A2,'Uczniowie (zanonimizowani)'!$F$2:$F$4580,B2,'Uczniowie (zanonimizowani)'!$K$2:$K$4580,"TAK") -> 0 | F2: =IFERROR(E2/D2,"") -> 0 | G2: =IFERROR(AVERAGEIFS('Uczniowie (zanonimizowani)'!$I$2:$I$4580,'Uczniowie (zanonimizowani)'!$B$2:$B$4580,C2,'Uczniowie (zanonimizowani)'!$E$2:$E$4580,A2,'Uczniowie (zanonimizowani)'!$F$2:$F$4580,B2),"") -> 0.76382838 | H2: =IFERROR(AVERAGEIFS('Uczniowie (zanonimizowani)'!$I$2:$I$4580,'Uczniowie (zanonimizowani)'!$B$2:$B$4580,C2,'Uczniowie (zanonimizowani)'!$E$2:$E$4580,A2,'Uczniowie (zanonimizowani)'!$F$2:$F$4580,B2,'Uczniowie (zanonimizowani)'!$K$2:$K$4580,"NIE"),"") -> 0.76382838 | I2: =IFERROR(H2-G2,"") -> 0
A3: 2020/2021 | B3: II | C3: 1M | D3: =COUNTIFS('Uczniowie (zanonimizowani)'!$B$2:$B$4580,C3,'Uczniowie (zanonimizowani)'!$E$2:$E$4580,A3,'Uczniowie (zanonimizowani)'!$F$2:$F$4580,B3) -> 15 | E3: =COUNTIFS('Uczniowie (zanonimizowani)'!$B$2:$B$4580,C3,'Uczniowie (zanonimizowani)'!$E$2:$E$4580,A3,'Uczniowie (zanonimizowani)'!$F$2:$F$4580,B3,'Uczniowie (zanonimizowani)'!$K$2:$K$4580,"TAK") -> 0 | F3: =IFERROR(E3/D3,"") -> 0 | G3: =IFERROR(AVERAGEIFS('Uczniowie (zanonimizowani)'!$I$2:$I$4580,'Uczniowie (zanonimizowani)'!$B$2:$B$4580,C3,'Uczniowie (zanonimizowani)'!$E$2:$E$4580,A3,'Uczniowie (zanonimizowani)'!$F$2:$F$4580,B3),"") -> 0.72107161 | H3: =IFERROR(AVERAGEIFS('Uczniowie (zanonimizowani)'!$I$2:$I$4580,'Uczniowie (zanonimizowani)'!$B$2:$B$4580,C3,'Uczniowie (zanonimizowani)'!$E$2:$E$4580,A3,'Uczniowie (zanonimizowani)'!$F$2:$F$4580,B3,'Uczniowie (zanonimizowani)'!$K$2:$K$4580,"NIE"),"") -> 0.72107161 | I3: =IFERROR(H3-G3,"") -> 0
A4: 2021/2022 | B4: I | C4: 1M | D4: =COUNTIFS('Uczniowie (zanonimizowani)'!$B$2:$B$4580,C4,'Uczniowie (zanonimizowani)'!$E$2:$E$4580,A4,'Uczniowie (zanonimizowani)'!$F$2:$F$4580,B4) -> 15 | E4: =COUNTIFS('Uczniowie (zanonimizowani)'!$B$2:$B$4580,C4,'Uczniowie (zanonimizowani)'!$E$2:$E$4580,A4,'Uczniowie (zanonimizowani)'!$F$2:$F$4580,B4,'Uczniowie (zanonimizowani)'!$K$2:$K$4580,"TAK") -> 1 | F4: =IFERROR(E4/D4,"") -> 0.066666667 | G4: =IFERROR(AVERAGEIFS('Uczniowie (zanonimizowani)'!$I$2:$I$4580,'Uczniowie (zanonimizowani)'!$B$2:$B$4580,C4,'Uczniowie (zanonimizowani)'!$E$2:$E$4580,A4,'Uczniowie (zanonimizowani)'!$F$2:$F$4580,B4),"") -> 0.80452745 | H4: =IFERROR(AVERAGEIFS('Uczniowie (zanonimizowani)'!$I$2:$I$4580,'Uczniowie (zanonimizowani)'!$B$2:$B$4580,C4,'Uczniowie (zanonimizowani)'!$E$2:$E$4580,A4,'Uczniowie (zanonimizowani)'!$F$2:$F$4580,B4,'Uczniowie (zanonimizowani)'!$K$2:$K$4580,"NIE"),"") -> 0.82306573 | I4: =IFERROR(H4-G4,"") -> 0.018538281
A5: 2021/2022 | B5: II | C5: 1M | D5: =COUNTIFS('Uczniowie (zanonimizowani)'!$B$2:$B$4580,C5,'Uczniowie (zanonimizowani)'!$E$2:$E$4580,A5,'Uczniowie (zanonimizowani)'!$F$2:$F$4580,B5) -> 16 | E5: =COUNTIFS('Uczniowie (zanonimizowani)'!$B$2:$B$4580,C5,'Uczniowie (zanonimizowani)'!$E$2:$E$4580,A5,'Uczniowie (zanonimizowani)'!$F$2:$F$4580,B5,'Uczniowie (zanonimizowani)'!$K$2:$K$4580,"TAK") -> 0 | F5: =IFERROR(E5/D5,"") -> 0 | G5: =IFERROR(AVERAGEIFS('Uczniowie (zanonimizowani)'!$I$2:$I$4580,'Uczniowie (zanonimizowani)'!$B$2:$B$4580,C5,'Uczniowie (zanonimizowani)'!$E$2:$E$4580,A5,'Uczniowie (zanonimizowani)'!$F$2:$F$4580,B5),"") -> 0.76535706 | H5: =IFERROR(AVERAGEIFS('Uczniowie (zanonimizowani)'!$I$2:$I$4580,'Uczniowie (zanonimizowani)'!$B$2:$B$4580,C5,'Uczniowie (zanonimizowani)'!$E$2:$E$4580,A5,'Uczniowie (zanonimizowani)'!$F$2:$F$4580,B5,'Uczniowie (zanonimizowani)'!$K$2:$K$4580,"NIE"),"") -> 0.76535706 | I5: =IFERROR(H5-G5,"") -> 0
A6: 2023/2024 | B6: I | C6: 1M | D6: =COUNTIFS('Uczniowie (zanonimizowani)'!$B$2:$B$4580,C6,'Uczniowie (zanonimizowani)'!$E$2:$E$4580,A6,'Uczniowie (zanonimizowani)'!$F$2:$F$4580,B6) -> 22 | E6: =COUNTIFS('Uczniowie (zanonimizowani)'!$B$2:$B$4580,C6,'Uczniowie (zanonimizowani)'!$E$2:$E$4580,A6,'Uczniowie (zanonimizowani)'!$F$2:$F$4580,B6,'Uczniowie (zanonimizowani)'!$K$2:$K$4580,"TAK") -> 1 | F6: =IFERROR(E6/D6,"") -> 0.045454545 | G6: =IFERROR(AVERAGEIFS('Uczniowie (zanonimizowani)'!$I$2:$I$4580,'Uczniowie (zanonimizowani)'!$B$2:$B$4580,C6,'Uczniowie (zanonimizowani)'!$E$2:$E$4580,A6,'Uczniowie (zanonimizowani)'!$F$2:$F$4580,B6),"") -> 0.75859219 | H6: =IFERROR(AVERAGEIFS('Uczniowie (zanonimizowani)'!$I$2:$I$4580,'Uczniowie (zanonimizowani)'!$B$2:$B$4580,C6,'Uczniowie (zanonimizowani)'!$E$2:$E$4580,A6,'Uczniowie (zanonimizowani)'!$F$2:$F$4580,B6,'Uczniowie (zanonimizowani)'!$K$2:$K$4580,"NIE"),"") -> 0.77303957 | I6: =IFERROR(H6-G6,"") -> 0.014447384
A7: 2023/2024 | B7: II | C7: 1M | D7: =COUNTIFS('Uczniowie (zanonimizowani)'!$B$2:$B$4580,C7,'Uczniowie (zanonimizowani)'!$E$2:$E$4580,A7,'Uczniowie (zanonimizowani)'!$F$2:$F$4580,B7) -> 24 | E7: =COUNTIFS('Uczniowie (zanonimizowani)'!$B$2:$B$4580,C7,'Uczniowie (zanonimizowani)'!$E$2:$E$4580,A7,'Uczniowie (zanonimizowani)'!$F$2:$F$4580,B7,'Uczniowie (zanonimizowani)'!$K$2:$K$4580,"TAK") -> 2 | F7: =IFERROR(E7/D7,"") -> 0.083333333 | G7: =IFERROR(AVERAGEIFS('Uczniowie (zanonimizowani)'!$I$2:$I$4580,'Uczniowie (zanonimizowani)'!$B$2:$B$4580,C7,'Uczniowie (zanonimizowani)'!$E$2:$E$4580,A7,'Uczniowie (zanonimizowani)'!$F$2:$F$4580,B7),"") -> 0.6227427 | H7: =IFERROR(AVERAGEIFS('Uczniowie (zanonimizowani)'!$I$2:$I$4580,'Uczniowie (zanonimizowani)'!$B$2:$B$4580,C7,'Uczniowie (zanonimizowani)'!$E$2:$E$4580,A7,'Uczniowie (zanonimizowani)'!$F$2:$F$4580,B7,'Uczniowie (zanonimizowani)'!$K$2:$K$4580,"NIE"),"") -> 0.67736162 | I7: =IFERROR(H7-G7,"") -> 0.054618926
A8: 2024/2025 | B8: I | C8: 1M | D8: =COUNTIFS('Uczniowie (zanonimizowani)'!$B$2:$B$4580,C8,'Uczniowie (zanonimizowani)'!$E$2:$E$4580,A8,'Uczniowie (zanonimizowani)'!$F$2:$F$4580,B8) -> 15 | E8: =COUNTIFS('Uczniowie (zanonimizowani)'!$B$2:$B$4580,C8,'Uczniowie (zanonimizowani)'!$E$2:$E$4580,A8,'Uczniowie (zanonimizowani)'!$F$2:$F$4580,B8,'Uczniowie (zanonimizowani)'!$K$2:$K$4580,"TAK") -> 1 | F8: =IFERROR(E8/D8,"") -> 0.066666667 | G8: =IFERROR(AVERAGEIFS('Uczniowie (zanonimizowani)'!$I$2:$I$4580,'Uczniowie (zanonimizowani)'!$B$2:$B$4580,C8,'Uczniowie (zanonimizowani)'!$E$2:$E$4580,A8,'Uczniowie (zanonimizowani)'!$F$2:$F$4580,B8),"") -> 0.71323632 | H8: =IFERROR(AVERAGEIFS('Uczniowie (zanonimizowani)'!$I$2:$I$4580,'Uczniowie (zanonimizowani)'!$B$2:$B$4580,C8,'Uczniowie (zanonimizowani)'!$E$2:$E$4580,A8,'Uczniowie (zanonimizowani)'!$F$2:$F$4580,B8,'Uczniowie (zanonimizowani)'!$K$2:$K$4580,"NIE"),"") -> 0.75687019 | I8: =IFERROR(H8-G8,"") -> 0.043633865
A9: 2024/2025 | B9: II | C9: 1M | D9: =COUNTIFS('Uczniowie (zanonimizowani)'!$B$2:$B$4580,C9,'Uczniowie (zanonimizowani)'!$E$2:$E$4580,A9,'Uczniowie (zanonimizowani)'!$F$2:$F$4580,B9) -> 18 | E9: =COUNTIFS('Uczniowie (zanonimizowani)'!$B$2:$B$4580,C9,'Uczniowie (zanonimizowani)'!$E$2:$E$4580,A9,'Uczniowie (zanonimizowani)'!$F$2:$F$4580,B9,'Uczniowie (zanonimizowani)'!$K$2:$K$4580,"TAK") -> 0 | F9: =IFERROR(E9/D9,"") -> 0 | G9: =IFERROR(AVERAGEIFS('Uczniowie (zanonimizowani)'!$I$2:$I$4580,'Uczniowie (zanonimizowani)'!$B$2:$B$4580,C9,'Uczniowie (zanonimizowani)'!$E$2:$E$4580,A9,'Uczniowie (zanonimizowani)'!$F$2:$F$4580,B9),"") -> 0.57040642 | H9: =IFERROR(AVERAGEIFS('Uczniowie (zanonimizowani)'!$I$2:$I$4580,'Uczniowie (zanonimizowani)'!$B$2:$B$4580,C9,'Uczniowie (zanonimizowani)'!$E$2:$E$4580,A9,'Uczniowie (zanonimizowani)'!$F$2:$F$4580,B9,'Uczniowie (zanonimizowani)'!$K$2:$K$4580,"NIE"),"") -> 0.57040642 | I9: =IFERROR(H9-G9,"") -> 0
A10: 2025/2026 | B10: I | C10: 1M | D10: =COUNTIFS('Uczniowie (zanonimizowani)'!$B$2:$B$4580,C10,'Uczniowie (zanonimizowani)'!$E$2:$E$4580,A10,'Uczniowie (zanonimizowani)'!$F$2:$F$4580,B10) -> 17 | E10: =COUNTIFS('Uczniowie (zanonimizowani)'!$B$2:$B$4580,C10,'Uczniowie (zanonimizowani)'!$E$2:$E$4580,A10,'Uczniowie (zanonimizowani)'!$F$2:$F$4580,B10,'Uczniowie (zanonimizowani)'!$K$2:$K$4580,"TAK") -> 0 | F10: =IFERROR(E10/D10,"") -> 0 | G10: =IFERROR(AVERAGEIFS('Uczniowie (zanonimizowani)'!$I$2:$I$4580,'Uczniowie (zanonimizowani)'!$B$2:$B$4580,C10,'Uczniowie (zanonimizowani)'!$E$2:$E$4580,A10,'Uczniowie (zanonimizowani)'!$F$2:$F$4580,B10),"") -> 0.71657247 | H10: =IFERROR(AVERAGEIFS('Uczniowie (zanonimizowani)'!$I$2:$I$4580,'Uczniowie (zanonimizowani)'!$B$2:$B$4580,C10,'Uczniowie (zanonimizowani)'!$E$2:$E$4580,A10,'Uczniowie (zanonimizowani)'!$F$2:$F$4580,B10,'Uczniowie (zanonimizowani)'!$K$2:$K$4580,"NIE"),"") -> 0.71657247 | I10: =IFERROR(H10-G10,"") -> 0
A11: 2025/2026 | B11: II | C11: 1M | D11: =COUNTIFS('Uczniowie (zanonimizowani)'!$B$2:$B$4580,C11,'Uczniowie (zanonimizowani)'!$E$2:$E$4580,A11,'Uczniowie (zanonimizowani)'!$F$2:$F$4580,B11) -> 19 | E11: =COUNTIFS('Uczniowie (zanonimizowani)'!$B$2:$B$4580,C11,'Uczniowie (zanonimizowani)'!$E$2:$E$4580,A11,'Uczniowie (zanonimizowani)'!$F$2:$F$4580,B11,'Uczniowie (zanonimizowani)'!$K$2:$K$4580,"TAK") -> 0 | F11: =IFERROR(E11/D11,"") -> 0 | G11: =IFERROR(AVERAGEIFS('Uczniowie (zanonimizowani)'!$I$2:$I$4580,'Uczniowie (zanonimizowani)'!$B$2:$B$4580,C11,'Uczniowie (zanonimizowani)'!$E$2:$E$4580,A11,'Uczniowie (zanonimizowani)'!$F$2:$F$4580,B11),"") -> 0.5194969 | H11: =IFERROR(AVERAGEIFS('Uczniowie (zanonimizowani)'!$I$2:$I$4580,'Uczniowie (zanonimizowani)'!$B$2:$B$4580,C11,'Uczniowie (zanonimizowani)'!$E$2:$E$4580,A11,'Uczniowie (zanonimizowani)'!$F$2:$F$4580,B11,'Uczniowie (zanonimizowani)'!$K$2:$K$4580,"NIE"),"") -> 0.5194969 | I11: =IFERROR(H11-G11,"") -> 0
A12: 2022/2023 | B12: I | C12: 1MK | D12: =COUNTIFS('Uczniowie (zanonimizowani)'!$B$2:$B$4580,C12,'Uczniowie (zanonimizowani)'!$E$2:$E$4580,A12,'Uczniowie (zanonimizowani)'!$F$2:$F$4580,B12) -> 33 | E12: =COUNTIFS('Uczniowie (zanonimizowani)'!$B$2:$B$4580,C12,'Uczniowie (zanonimizowani)'!$E$2:$E$4580,A12,'Uczniowie (zanonimizowani)'!$F$2:$F$4580,B12,'Uczniowie (zanonimizowani)'!$K$2:$K$4580,"TAK") -> 0 | F12: =IFERROR(E12/D12,"") -> 0 | G12: =IFERROR(AVERAGEIFS('Uczniowie (zanonimizowani)'!$I$2:$I$4580,'Uczniowie (zanonimizowani)'!$B$2:$B$4580,C12,'Uczniowie (zanonimizowani)'!$E$2:$E$4580,A12,'Uczniowie (zanonimizowani)'!$F$2:$F$4580,B12),"") -> 0.80047511 | H12: =IFERROR(AVERAGEIFS('Uczniowie (zanonimizowani)'!$I$2:$I$4580,'Uczniowie (zanonimizowani)'!$B$2:$B$4580,C12,'Uczniowie (zanonimizowani)'!$E$2:$E$4580,A12,'Uczniowie (zanonimizowani)'!$F$2:$F$4580,B12,'Uczniowie (zanonimizowani)'!$K$2:$K$4580,"NIE"),"") -> 0.80047511 | I12: =IFERROR(H12-G12,"") -> 0
A13: 2022/2023 | B13: II | C13: 1MK | D13: =COUNTIFS('Uczniowie (zanonimizowani)'!$B$2:$B$4580,C13,'Uczniowie (zanonimizowani)'!$E$2:$E$4580,A13,'Uczniowie (zanonimizowani)'!$F$2:$F$4580,B13) -> 30 | E13: =COUNTIFS('Uczniowie (zanonimizowani)'!$B$2:$B$4580,C13,'Uczniowie (zanonimizowani)'!$E$2:$E$4580,A13,'Uczniowie (zanonimizowani)'!$F$2:$F$4580,B13,'Uczniowie (zanonimizowani)'!$K$2:$K$4580,"TAK") -> 1 | F13: =IFERROR(E13/D13,"") -> 0.033333333 | G13: =IFERROR(AVERAGEIFS('Uczniowie (zanonimizowani)'!$I$2:$I$4580,'Uczniowie (zanonimizowani)'!$B$2:$B$4580,C13,'Uczniowie (zanonimizowani)'!$E$2:$E$4580,A13,'Uczniowie (zanonimizowani)'!$F$2:$F$4580,B13),"") -> 0.73482891 | H13: =IFERROR(AVERAGEIFS('Uczniowie (zanonimizowani)'!$I$2:$I$4580,'Uczniowie (zanonimizowani)'!$B$2:$B$4580,C13,'Uczniowie (zanonimizowani)'!$E$2:$E$4580,A13,'Uczniowie (zanonimizowani)'!$F$2:$F$4580,B13,'Uczniowie (zanonimizowani)'!$K$2:$K$4580,"NIE"),"") -> 0.75600873 | I13: =IFERROR(H13-G13,"") -> 0.021179823
... A217: 2024/2025 | B217: II | C217: 5TŻ5 | D217: =COUNTIFS('Uczniowie (zanonimizowani)'!$B$2:$B$4580,C217,'Uczniowie (zanonimizowani)'!$E$2:$E$4580,A217,'Uczniowie (zanonimizowani)'!$F$2:$F$4580,B217) -> 12 | E217: =COUNTIFS('Uczniowie (zanonimizowani)'!$B$2:$B$4580,C217,'Uczniowie (zanonimizowani)'!$E$2:$E$4580,A217,'Uczniowie (zanonimizowani)'!$F$2:$F$4580,B217,'Uczniowie (zanonimizowani)'!$K$2:$K$4580,"TAK") -> 1 | F217: =IFERROR(E217/D217,"") -> 0.083333333 | G217: =IFERROR(AVERAGEIFS('Uczniowie (zanonimizowani)'!$I$2:$I$4580,'Uczniowie (zanonimizowani)'!$B$2:$B$4580,C217,'Uczniowie (zanonimizowani)'!$E$2:$E$4580,A217,'Uczniowie (zanonimizowani)'!$F$2:$F$4580,B217),"") -> 0.60772044 | H217: =IFERROR(AVERAGEIFS('Uczniowie (zanonimizowani)'!$I$2:$I$4580,'Uczniowie (zanonimizowani)'!$B$2:$B$4580,C217,'Uczniowie (zanonimizowani)'!$E$2:$E$4580,A217,'Uczniowie (zanonimizowani)'!$F$2:$F$4580,B217,'Uczniowie (zanonimizowani)'!$K$2:$K$4580,"NIE"),"") -> 0.640444 | I217: =IFERROR(H217-G217,"") -> 0.032723568
